WARNING  2018-02-04,08:59:56.208 THU@rpi8:ThuZeroService:finish:55 - stopping
WARNING  2018-02-04,08:59:56.210 THU@rpi8:ThuZeroService:finish:60 -    stopped
ERROR    2018-02-04,09:00:02.690 CAM@rpi8:core:_print_traceback:130 -  - (<class 'picamera.exc.PiCameraMMALError'>, PiCameraMMALError('Failed to enable connection: Out of resources',), <traceback object at 0x705f6328>)
Traceback (most recent call last):
  File "/home/ncb/berryconda3/lib/python3.6/site-packages/zerorpc/core.py", line 153, in _async_task
    functor.pattern.process_call(self._context, bufchan, event, functor)
  File "/home/ncb/berryconda3/lib/python3.6/site-packages/zerorpc/patterns.py", line 30, in process_call
    result = functor(*req_event.args)
  File "/home/ncb/berryconda3/lib/python3.6/site-packages/zerorpc/decorators.py", line 44, in __call__
    return self._functor(*args, **kargs)
  File "/home/ncb/code/ethoservice/ethoservice/CamZeroService.py", line 61, in setup
    self.camera = picamera.PiCamera()
  File "/home/ncb/berryconda3/lib/python3.6/site-packages/picamera/camera.py", line 433, in __init__
    self._init_preview()
  File "/home/ncb/berryconda3/lib/python3.6/site-packages/picamera/camera.py", line 513, in _init_preview
    self, self._camera.outputs[self.CAMERA_PREVIEW_PORT])
  File "/home/ncb/berryconda3/lib/python3.6/site-packages/picamera/renderers.py", line 558, in __init__
    self.renderer.inputs[0].connect(source).enable()
  File "/home/ncb/berryconda3/lib/python3.6/site-packages/picamera/mmalobj.py", line 2212, in enable
    prefix="Failed to enable connection")
  File "/home/ncb/berryconda3/lib/python3.6/site-packages/picamera/exc.py", line 184, in mmal_check
    raise PiCameraMMALError(status, prefix)
picamera.exc.PiCameraMMALError: Failed to enable connection: Out of resources
