WARNING  2018-01-29,15:59:17.136 OPT@rpi8:OptZeroService:finish:56 - stopping
ERROR    2018-01-29,15:59:17.663 OPT@rpi8:core:_print_traceback:130 -  - (<class 'gpiozero.exc.GPIOPinInUse'>, GPIOPinInUse('pin 3 is already in use by <gpiozero.LED object on pin GPIO3, active_high=True, is_active=False>',), <traceback object at 0x73826508>)
Traceback (most recent call last):
  File "/home/ncb/berryconda3/lib/python3.6/site-packages/zerorpc/core.py", line 153, in _async_task
    functor.pattern.process_call(self._context, bufchan, event, functor)
  File "/home/ncb/berryconda3/lib/python3.6/site-packages/zerorpc/patterns.py", line 30, in process_call
    result = functor(*req_event.args)
  File "/home/ncb/berryconda3/lib/python3.6/site-packages/zerorpc/decorators.py", line 44, in __call__
    return self._functor(*args, **kargs)
  File "/home/ncb/code/ethoservice/ethoservice/OptZeroService.py", line 26, in setup
    self.LED = gpiozero.LED(self.pin)
  File "/home/ncb/berryconda3/lib/python3.6/site-packages/gpiozero/devices.py", line 95, in __call__
    self = super(GPIOMeta, cls).__call__(*args, **kwargs)
  File "/home/ncb/berryconda3/lib/python3.6/site-packages/gpiozero/output_devices.py", line 141, in __init__
    pin, active_high, initial_value, pin_factory=pin_factory
  File "/home/ncb/berryconda3/lib/python3.6/site-packages/gpiozero/output_devices.py", line 47, in __init__
    super(OutputDevice, self).__init__(pin, pin_factory=pin_factory)
  File "/home/ncb/berryconda3/lib/python3.6/site-packages/gpiozero/mixins.py", line 69, in __init__
    super(SourceMixin, self).__init__(*args, **kwargs)
  File "/home/ncb/berryconda3/lib/python3.6/site-packages/gpiozero/devices.py", line 373, in __init__
    self.pin_factory.reserve_pins(self, pin)
  File "/home/ncb/berryconda3/lib/python3.6/site-packages/gpiozero/pins/__init__.py", line 62, in reserve_pins
    (pin, reserver))
gpiozero.exc.GPIOPinInUse: pin 3 is already in use by <gpiozero.LED object on pin GPIO3, active_high=True, is_active=False>
WARNING  2018-01-29,16:01:52.205 OPT@rpi8:OptZeroService:finish:56 - stopping
ERROR    2018-01-29,16:01:52.806 OPT@rpi8:core:_print_traceback:130 -  - (<class 'gpiozero.exc.GPIOPinInUse'>, GPIOPinInUse('pin 3 is already in use by <gpiozero.LED object on pin GPIO3, active_high=True, is_active=False>',), <traceback object at 0x73826800>)
Traceback (most recent call last):
  File "/home/ncb/berryconda3/lib/python3.6/site-packages/zerorpc/core.py", line 153, in _async_task
    functor.pattern.process_call(self._context, bufchan, event, functor)
  File "/home/ncb/berryconda3/lib/python3.6/site-packages/zerorpc/patterns.py", line 30, in process_call
    result = functor(*req_event.args)
  File "/home/ncb/berryconda3/lib/python3.6/site-packages/zerorpc/decorators.py", line 44, in __call__
    return self._functor(*args, **kargs)
  File "/home/ncb/code/ethoservice/ethoservice/OptZeroService.py", line 26, in setup
    self.LED = gpiozero.LED(self.pin)
  File "/home/ncb/berryconda3/lib/python3.6/site-packages/gpiozero/devices.py", line 95, in __call__
    self = super(GPIOMeta, cls).__call__(*args, **kwargs)
  File "/home/ncb/berryconda3/lib/python3.6/site-packages/gpiozero/output_devices.py", line 141, in __init__
    pin, active_high, initial_value, pin_factory=pin_factory
  File "/home/ncb/berryconda3/lib/python3.6/site-packages/gpiozero/output_devices.py", line 47, in __init__
    super(OutputDevice, self).__init__(pin, pin_factory=pin_factory)
  File "/home/ncb/berryconda3/lib/python3.6/site-packages/gpiozero/mixins.py", line 69, in __init__
    super(SourceMixin, self).__init__(*args, **kwargs)
  File "/home/ncb/berryconda3/lib/python3.6/site-packages/gpiozero/devices.py", line 373, in __init__
    self.pin_factory.reserve_pins(self, pin)
  File "/home/ncb/berryconda3/lib/python3.6/site-packages/gpiozero/pins/__init__.py", line 62, in reserve_pins
    (pin, reserver))
gpiozero.exc.GPIOPinInUse: pin 3 is already in use by <gpiozero.LED object on pin GPIO3, active_high=True, is_active=False>
WARNING  2018-01-29,16:10:19.638 OPT@rpi8:OptZeroService:finish:57 - stopping
ERROR    2018-01-29,16:10:20.147 OPT@rpi8:core:_print_traceback:130 -  - (<class 'gpiozero.exc.GPIOPinInUse'>, GPIOPinInUse('pin 3 is already in use by <gpiozero.LED object on pin GPIO3, active_high=True, is_active=False>',), <traceback object at 0x738555f8>)
Traceback (most recent call last):
  File "/home/ncb/berryconda3/lib/python3.6/site-packages/zerorpc/core.py", line 153, in _async_task
    functor.pattern.process_call(self._context, bufchan, event, functor)
  File "/home/ncb/berryconda3/lib/python3.6/site-packages/zerorpc/patterns.py", line 30, in process_call
    result = functor(*req_event.args)
  File "/home/ncb/berryconda3/lib/python3.6/site-packages/zerorpc/decorators.py", line 44, in __call__
    return self._functor(*args, **kargs)
  File "/home/ncb/code/ethoservice/ethoservice/OptZeroService.py", line 26, in setup
    self.LED = gpiozero.LED(self.pin)
  File "/home/ncb/berryconda3/lib/python3.6/site-packages/gpiozero/devices.py", line 95, in __call__
    self = super(GPIOMeta, cls).__call__(*args, **kwargs)
  File "/home/ncb/berryconda3/lib/python3.6/site-packages/gpiozero/output_devices.py", line 141, in __init__
    pin, active_high, initial_value, pin_factory=pin_factory
  File "/home/ncb/berryconda3/lib/python3.6/site-packages/gpiozero/output_devices.py", line 47, in __init__
    super(OutputDevice, self).__init__(pin, pin_factory=pin_factory)
  File "/home/ncb/berryconda3/lib/python3.6/site-packages/gpiozero/mixins.py", line 69, in __init__
    super(SourceMixin, self).__init__(*args, **kwargs)
  File "/home/ncb/berryconda3/lib/python3.6/site-packages/gpiozero/devices.py", line 373, in __init__
    self.pin_factory.reserve_pins(self, pin)
  File "/home/ncb/berryconda3/lib/python3.6/site-packages/gpiozero/pins/__init__.py", line 62, in reserve_pins
    (pin, reserver))
gpiozero.exc.GPIOPinInUse: pin 3 is already in use by <gpiozero.LED object on pin GPIO3, active_high=True, is_active=False>
ERROR    2018-01-29,16:10:28.817 OPT@rpi8:core:_print_traceback:130 -  - (<class 'NameError'>, NameError("name 'LED_blinkduration' is not defined",), <traceback object at 0x736d9030>)
Traceback (most recent call last):
  File "/home/ncb/berryconda3/lib/python3.6/site-packages/zerorpc/core.py", line 153, in _async_task
    functor.pattern.process_call(self._context, bufchan, event, functor)
  File "/home/ncb/berryconda3/lib/python3.6/site-packages/zerorpc/patterns.py", line 30, in process_call
    result = functor(*req_event.args)
  File "/home/ncb/berryconda3/lib/python3.6/site-packages/zerorpc/decorators.py", line 44, in __call__
    return self._functor(*args, **kargs)
  File "/home/ncb/code/ethoservice/ethoservice/OptZeroService.py", line 36, in start
    self.LED.blink(on_time=LED_blinkduration, off_time=LED_blinkinterval-LED_blinkduration, n=10)
NameError: name 'LED_blinkduration' is not defined
WARNING  2018-01-29,16:10:49.158 OPT@rpi8:OptZeroService:finish:57 - stopping
ERROR    2018-01-29,16:10:49.676 OPT@rpi8:core:_print_traceback:130 -  - (<class 'gpiozero.exc.GPIOPinInUse'>, GPIOPinInUse('pin 3 is already in use by <gpiozero.LED object on pin GPIO3, active_high=True, is_active=False>',), <traceback object at 0x736d9a08>)
Traceback (most recent call last):
  File "/home/ncb/berryconda3/lib/python3.6/site-packages/zerorpc/core.py", line 153, in _async_task
    functor.pattern.process_call(self._context, bufchan, event, functor)
  File "/home/ncb/berryconda3/lib/python3.6/site-packages/zerorpc/patterns.py", line 30, in process_call
    result = functor(*req_event.args)
  File "/home/ncb/berryconda3/lib/python3.6/site-packages/zerorpc/decorators.py", line 44, in __call__
    return self._functor(*args, **kargs)
  File "/home/ncb/code/ethoservice/ethoservice/OptZeroService.py", line 26, in setup
    self.LED = gpiozero.LED(self.pin)
  File "/home/ncb/berryconda3/lib/python3.6/site-packages/gpiozero/devices.py", line 95, in __call__
    self = super(GPIOMeta, cls).__call__(*args, **kwargs)
  File "/home/ncb/berryconda3/lib/python3.6/site-packages/gpiozero/output_devices.py", line 141, in __init__
    pin, active_high, initial_value, pin_factory=pin_factory
  File "/home/ncb/berryconda3/lib/python3.6/site-packages/gpiozero/output_devices.py", line 47, in __init__
    super(OutputDevice, self).__init__(pin, pin_factory=pin_factory)
  File "/home/ncb/berryconda3/lib/python3.6/site-packages/gpiozero/mixins.py", line 69, in __init__
    super(SourceMixin, self).__init__(*args, **kwargs)
  File "/home/ncb/berryconda3/lib/python3.6/site-packages/gpiozero/devices.py", line 373, in __init__
    self.pin_factory.reserve_pins(self, pin)
  File "/home/ncb/berryconda3/lib/python3.6/site-packages/gpiozero/pins/__init__.py", line 62, in reserve_pins
    (pin, reserver))
gpiozero.exc.GPIOPinInUse: pin 3 is already in use by <gpiozero.LED object on pin GPIO3, active_high=True, is_active=False>
ERROR    2018-01-29,16:10:56.764 OPT@rpi8:core:_print_traceback:130 -  - (<class 'NameError'>, NameError("name 'LED_blinkduration' is not defined",), <traceback object at 0x7384f058>)
Traceback (most recent call last):
  File "/home/ncb/berryconda3/lib/python3.6/site-packages/zerorpc/core.py", line 153, in _async_task
    functor.pattern.process_call(self._context, bufchan, event, functor)
  File "/home/ncb/berryconda3/lib/python3.6/site-packages/zerorpc/patterns.py", line 30, in process_call
    result = functor(*req_event.args)
  File "/home/ncb/berryconda3/lib/python3.6/site-packages/zerorpc/decorators.py", line 44, in __call__
    return self._functor(*args, **kargs)
  File "/home/ncb/code/ethoservice/ethoservice/OptZeroService.py", line 36, in start
    self.LED.blink(on_time=LED_blinkduration, off_time=LED_blinkinterval-LED_blinkduration, n=10)
NameError: name 'LED_blinkduration' is not defined
WARNING  2018-01-29,16:15:20.028 OPT@rpi8:OptZeroService:finish:57 - stopping
WARNING  2018-01-29,16:16:47.256 OPT@rpi8:OptZeroService:finish:55 - stopping
WARNING  2018-01-29,16:17:35.077 OPT@rpi8:OptZeroService:finish:55 - stopping
ERROR    2018-01-29,16:17:35.479 OPT@rpi8:core:_print_traceback:130 -  - (<class 'gpiozero.exc.GPIOPinInUse'>, GPIOPinInUse('pin 3 is already in use by <gpiozero.LED object on pin GPIO3, active_high=True, is_active=False>',), <traceback object at 0x738332d8>)
Traceback (most recent call last):
  File "/home/ncb/berryconda3/lib/python3.6/site-packages/zerorpc/core.py", line 153, in _async_task
    functor.pattern.process_call(self._context, bufchan, event, functor)
  File "/home/ncb/berryconda3/lib/python3.6/site-packages/zerorpc/patterns.py", line 30, in process_call
    result = functor(*req_event.args)
  File "/home/ncb/berryconda3/lib/python3.6/site-packages/zerorpc/decorators.py", line 44, in __call__
    return self._functor(*args, **kargs)
  File "/home/ncb/code/ethoservice/ethoservice/OptZeroService.py", line 27, in setup
    self.LED = gpiozero.LED(self.pin)
  File "/home/ncb/berryconda3/lib/python3.6/site-packages/gpiozero/devices.py", line 95, in __call__
    self = super(GPIOMeta, cls).__call__(*args, **kwargs)
  File "/home/ncb/berryconda3/lib/python3.6/site-packages/gpiozero/output_devices.py", line 141, in __init__
    pin, active_high, initial_value, pin_factory=pin_factory
  File "/home/ncb/berryconda3/lib/python3.6/site-packages/gpiozero/output_devices.py", line 47, in __init__
    super(OutputDevice, self).__init__(pin, pin_factory=pin_factory)
  File "/home/ncb/berryconda3/lib/python3.6/site-packages/gpiozero/mixins.py", line 69, in __init__
    super(SourceMixin, self).__init__(*args, **kwargs)
  File "/home/ncb/berryconda3/lib/python3.6/site-packages/gpiozero/devices.py", line 373, in __init__
    self.pin_factory.reserve_pins(self, pin)
  File "/home/ncb/berryconda3/lib/python3.6/site-packages/gpiozero/pins/__init__.py", line 62, in reserve_pins
    (pin, reserver))
gpiozero.exc.GPIOPinInUse: pin 3 is already in use by <gpiozero.LED object on pin GPIO3, active_high=True, is_active=False>
WARNING  2018-01-29,16:22:46.874 OPT@rpi8:OptZeroService:finish:55 - stopping
WARNING  2018-01-29,16:25:18.138 CAM@rpi8:CamZeroService:finish:97 - stopping recording
WARNING  2018-01-29,16:25:18.172 CAM@rpi8:CamZeroService:finish:100 -    stopped recording
WARNING  2018-01-29,16:25:18.187 CAM@rpi8:CamZeroService:finish:97 - stopping recording
WARNING  2018-01-29,16:25:18.188 CAM@rpi8:CamZeroService:finish:102 -    was not recording
ERROR    2018-01-29,16:27:10.191 THU@rpi8:core:_print_traceback:130 -  - (<class 'TypeError'>, TypeError('setup() takes 4 positional arguments but 5 were given',), <traceback object at 0x73be2b48>)
Traceback (most recent call last):
  File "/home/ncb/berryconda3/lib/python3.6/site-packages/zerorpc/core.py", line 153, in _async_task
    functor.pattern.process_call(self._context, bufchan, event, functor)
  File "/home/ncb/berryconda3/lib/python3.6/site-packages/zerorpc/patterns.py", line 30, in process_call
    result = functor(*req_event.args)
  File "/home/ncb/berryconda3/lib/python3.6/site-packages/zerorpc/decorators.py", line 44, in __call__
    return self._functor(*args, **kargs)
TypeError: setup() takes 4 positional arguments but 5 were given
ERROR    2018-01-29,16:27:59.388 OPT@rpi8:core:_print_traceback:130 -  - (<class 'TypeError'>, TypeError("unsupported operand type(s) for -: 'str' and 'str'",), <traceback object at 0x75932bc0>)
Traceback (most recent call last):
  File "/home/ncb/berryconda3/lib/python3.6/site-packages/zerorpc/core.py", line 153, in _async_task
    functor.pattern.process_call(self._context, bufchan, event, functor)
  File "/home/ncb/berryconda3/lib/python3.6/site-packages/zerorpc/patterns.py", line 30, in process_call
    result = functor(*req_event.args)
  File "/home/ncb/berryconda3/lib/python3.6/site-packages/zerorpc/decorators.py", line 44, in __call__
    return self._functor(*args, **kargs)
  File "/home/ncb/code/ethoservice/ethoservice/OptZeroService.py", line 26, in setup
    self.blinkpause = self.LED_blinkinterval-self.LED_blinkduration
TypeError: unsupported operand type(s) for -: 'str' and 'str'
ERROR    2018-01-29,16:29:55.519 OPT@rpi8:core:_print_traceback:130 -  - (<class 'TypeError'>, TypeError("'<=' not supported between instances of 'int' and 'str'",), <traceback object at 0x75d12418>)
Traceback (most recent call last):
  File "/home/ncb/berryconda3/lib/python3.6/site-packages/zerorpc/core.py", line 153, in _async_task
    functor.pattern.process_call(self._context, bufchan, event, functor)
  File "/home/ncb/berryconda3/lib/python3.6/site-packages/zerorpc/patterns.py", line 30, in process_call
    result = functor(*req_event.args)
  File "/home/ncb/berryconda3/lib/python3.6/site-packages/zerorpc/decorators.py", line 44, in __call__
    return self._functor(*args, **kargs)
  File "/home/ncb/code/ethoservice/ethoservice/OptZeroService.py", line 27, in setup
    self.LED = gpiozero.LED(self.pin)
  File "/home/ncb/berryconda3/lib/python3.6/site-packages/gpiozero/devices.py", line 95, in __call__
    self = super(GPIOMeta, cls).__call__(*args, **kwargs)
  File "/home/ncb/berryconda3/lib/python3.6/site-packages/gpiozero/output_devices.py", line 141, in __init__
    pin, active_high, initial_value, pin_factory=pin_factory
  File "/home/ncb/berryconda3/lib/python3.6/site-packages/gpiozero/output_devices.py", line 47, in __init__
    super(OutputDevice, self).__init__(pin, pin_factory=pin_factory)
  File "/home/ncb/berryconda3/lib/python3.6/site-packages/gpiozero/mixins.py", line 69, in __init__
    super(SourceMixin, self).__init__(*args, **kwargs)
  File "/home/ncb/berryconda3/lib/python3.6/site-packages/gpiozero/devices.py", line 374, in __init__
    pin = self.pin_factory.pin(pin)
  File "/home/ncb/berryconda3/lib/python3.6/site-packages/gpiozero/pins/pi.py", line 69, in pin
    n = self._to_gpio(spec)
  File "/home/ncb/berryconda3/lib/python3.6/site-packages/gpiozero/pins/pi.py", line 81, in _to_gpio
    if not 0 <= spec < 54:
TypeError: '<=' not supported between instances of 'int' and 'str'
